Workbook

Sheet Call-FollowUp form
A1: รายงานการติดตามลูกค้าประจำวัน ( Call/Visit Follow up Form )
A4: วันที่
A5: ชื่อพนักงาน
A6: รหัสพนักงาน
A9: ลำดับที่ | B9: หมายเลขสมาชิก | C9: ชื่อบริษัท-ชื่อเจ้าของกิจการ | D9: ที่อยู่ (หมู่ที่/ตำบล/อำเภอ/จังหวัด) | F9: เบอร์โทรศัพท์ | G9: กลุ่มลูกค้า | H9: ติดต่อ | L9: หมายเหตุ
A10: No. | B10: Member card | C10: Company Name | D10: Address | F10: Telephone | G10: ประเภท 4 | H10: ได้ | J10: ไม่ได้ | L10: Remark
A11: 1
A12: 2
A13: 3
A14: 4
A15: 5
A16: 6
A17: 7
A18: 8
A19: 9
A20: 10
A21: 11
A22: 12
... A25: 15
A27: * กรุณาลงบันทึกรายละเอียดลูกค้าทุกราย และข้อมูลให้ครบถ้วน
L28: (ผู้ตรวจสอบ M1/M2/M3/M4 Duty Mgr.)

Sheet Call_Form
D2: แบบฟอร์มการติดตามลูกค้า (Call/Visit Form)
A4: สาขา
H5: ผู้ตรวจสอบ
A6: No. | B6: วัน/เดือน/ปี | C6: หมายเลขบัตรสมาชิก | D6: ชื่อ นามสกุล | E6: ชื่อกิจการ | F6: พื้นที่ (ตำบล/อำเภอ) | G6: ลูกค้า เก่า/ใหม่ | H6: เจ้าหน้าที่ B2B | I6: M1/M2/DUTY STORE

Sheet Form_เพิ่มลูกค้า
K1: ดูจาก Sheet Customer Struture
E2: จำเป็น | H2: จำเป็น | I2: จำเป็น | J2: จำเป็น | K2: จำเป็น | L2: จำเป็น | M2: จำเป็น | U2: จำเป็น | V2: จำเป็น | W2: จำเป็น | X2: จำเป็น | Y2: จำเป็น GPS Location | AF2: **ห้ามแก้ไขเปลี่ยนแปลงข้อมูล**
A3: ลำดับ | B3: วัน/เดือน/ปี | C3: รหัสสาขา | D3: ชื่อสาขา | E3: หมายเลขบัตรสมาชิก BIGCARD (16หลัก) | F3: จำนวนอักษร | G3: หมายเลขบัตร ประชาชน | H3: ชื่อ นามสกุล ผู้ถือบัตร | I3: ชื่อกิจการ | J3: โทรศัพท์ (ผูกกับ บัตร BIG CARD) | K3: กลุ่มลูกค้า ประเภท 2 | L3: กลุ่มลูกค้า ประเภท 3 | M3: กลุ่มลูกค้า ประเภท 4 | N3: ระยะทาง | O3: ประมาณการซื้อ/เดือน | P3: ชื่อผู้ชื้อ | Q3: เบอร์ผู้ซื้อ / ติดต่อ | R3: ลูกค้าเก่า/ใหม่ | S3: ผู้ทำการสำรวจ | T3: วิธีการเข้าหาลูกค้า | U3: เลขที่/หมู่บ้าน /หมู่/ถนน | V3: ตำบล | W3: อำเภอ | X3: จังหวัด | Y3: ละติจูด | Z3: ลองติจูด | AA3: พฤติกรรมการซื้อ | AB3: ความถี่ | AC3: ช่องทางขาย | AD3: วันเกิดลูกค้า | AE3: Remark | AF3: หมายเลขบัตรสมาชิก | AG3: BIGC | AH3: LEVEL 2 | AI3: LEVEL 3 | AJ3: LEVEL 4 | AK3: H/F
A4: 1 | B4: 243888 | C4: 11111 | D4: Bangkok | E4: 1115111111111111 | F4: =LEN(E4) -> 16 | G4: 1111111111111 | H4: คุณสีแดง ชอบสีเขียว | I4: ร้านข้าวราดแกงสีชมพู | J4: 0999999999 | K4: 8 HoReCa | L4: 82 Restaurant | M4: 8212 ร้านอาหารประเภทก๋วยเตี๋ยว/ผ้ดไท/ราดหน้า/ก๋วยจั๊บ | N4: 3 กม. | O4: 5000 | P4: คุณณัฐพล อินต๊ะวิกุล | Q4: 0930209678 | R4: เก่า | S4: Sale Horeca | T4: walk in | U4: ตลาดไฟฟ้า | V4: เสม็ด | W4: เมือง | X4: ชลบุรี | Y4: 13.3312831 | Z4: 100.942641 | AA4: สันคอหมู ไก่ หนังหมูซอย เครื่องปรุง | AB4: 5ครั้ง/เดือน | AC4: Line&Telephone | AD4: 1 ม.ค. 2499 | AF4: =E4 -> 1115111111111111 | AG4: BIGC | AH4: =LEFT(K4,1) -> 8 | AI4: =LEFT(L4,2) -> 82 | AJ4: =LEFT(M4,4) -> 8212 | AK4: =IF(VLOOKUP($AI:$AI,'Customer Structure'!$G:$I,3,0)="Food Service","F","H") -> F
A6: 3 | F6: =LEN(E6) -> 0 | AF6: =E6 -> 0 | AG6: BIGC | AH6: =LEFT(K6,1) | AI6: =LEFT(L6,2) | AJ6: =LEFT(M6,4) | AK6: =IF(VLOOKUP($AI:$AI,'Customer Structure'!$G:$I,3,0)="Food Service","F","H") -> #N/A
A7: 4 | F7: =LEN(E7) -> 0 | AF7: =E7 -> 0 | AG7: BIGC | AH7: =LEFT(K7,1) | AI7: =LEFT(L7,2) | AJ7: =LEFT(M7,4) | AK7: =IF(VLOOKUP($AI:$AI,'Customer Structure'!$G:$I,3,0)="Food Service","F","H") -> #N/A
A8: 5 | F8: =LEN(E8) -> 0 | AF8: =E8 -> 0 | AG8: BIGC | AH8: =LEFT(K8,1) | AI8: =LEFT(L8,2) | AJ8: =LEFT(M8,4) | AK8: =IF(VLOOKUP($AI:$AI,'Customer Structure'!$G:$I,3,0)="Food Service","F","H") -> #N/A
A9: 6 | F9: =LEN(E9) -> 0 | AF9: =E9 -> 0 | AG9: BIGC | AH9: =LEFT(K9,1) | AI9: =LEFT(L9,2) | AJ9: =LEFT(M9,4) | AK9: =IF(VLOOKUP($AI:$AI,'Customer Structure'!$G:$I,3,0)="Food Service","F","H") -> #N/A
A10: 7 | F10: =LEN(E10) -> 0 | AF10: =E10 -> 0 | AG10: BIGC | AH10: =LEFT(K10,1) | AI10: =LEFT(L10,2) | AJ10: =LEFT(M10,4) | AK10: =IF(VLOOKUP($AI:$AI,'Customer Structure'!$G:$I,3,0)="Food Service","F","H") -> #N/A
A11: 8 | F11: =LEN(E11) -> 0 | AF11: =E11 -> 0 | AG11: BIGC | AH11: =LEFT(K11,1) | AI11: =LEFT(L11,2) | AJ11: =LEFT(M11,4) | AK11: =IF(VLOOKUP($AI:$AI,'Customer Structure'!$G:$I,3,0)="Food Service","F","H") -> #N/A
A12: 9 | F12: =LEN(E12) -> 0 | AF12: =E12 -> 0 | AG12: BIGC | AH12: =LEFT(K12,1) | AI12: =LEFT(L12,2) | AJ12: =LEFT(M12,4) | AK12: =IF(VLOOKUP($AI:$AI,'Customer Structure'!$G:$I,3,0)="Food Service","F","H") -> #N/A
A13: 10 | F13: =LEN(E13) -> 0 | AF13: =E13 -> 0 | AG13: BIGC | AH13: =LEFT(K13,1) | AI13: =LEFT(L13,2) | AJ13: =LEFT(M13,4) | AK13: =IF(VLOOKUP($AI:$AI,'Customer Structure'!$G:$I,3,0)="Food Service","F","H") -> #N/A
A14: 11 | F14: =LEN(E14) -> 0 | AF14: =E14 -> 0 | AG14: BIGC | AH14: =LEFT(K14,1) | AI14: =LEFT(L14,2) | AJ14: =LEFT(M14,4) | AK14: =IF(VLOOKUP($AI:$AI,'Customer Structure'!$G:$I,3,0)="Food Service","F","H") -> #N/A
A15: 12 | F15: =LEN(E15) -> 0 | AF15: =E15 -> 0 | AG15: BIGC | AH15: =LEFT(K15,1) | AI15: =LEFT(L15,2) | AJ15: =LEFT(M15,4) | AK15: =IF(VLOOKUP($AI:$AI,'Customer Structure'!$G:$I,3,0)="Food Service","F","H") -> #N/A
A16: 13 | F16: =LEN(E16) -> 0 | AF16: =E16 -> 0 | AG16: BIGC | AH16: =LEFT(K16,1) | AI16: =LEFT(L16,2) | AJ16: =LEFT(M16,4) | AK16: =IF(VLOOKUP($AI:$AI,'Customer Structure'!$G:$I,3,0)="Food Service","F","H") -> #N/A
A17: 14 | F17: =LEN(E17) -> 0 | AF17: =E17 -> 0 | AG17: BIGC | AH17: =LEFT(K17,1) | AI17: =LEFT(L17,2) | AJ17: =LEFT(M17,4) | AK17: =IF(VLOOKUP($AI:$AI,'Customer Structure'!$G:$I,3,0)="Food Service","F","H") -> #N/A
... A103: 100 | F103: =LEN(E103) -> 0 | AF103: =E103 -> 0 | AG103: BIGC | AH103: =LEFT(K103,1) | AI103: =LEFT(L103,2) | AJ103: =LEFT(M103,4) | AK103: =IF(VLOOKUP($AI:$AI,'Customer Structure'!$G:$I,3,0)="Food Service","F","H") -> #N/A

Sheet Customer Structure
B2: ประเภทบัตรสมาชิก | C2: กลุ่มลูกค้า ประเภท 2 | D2: กลุ่มลูกค้า ประเภท 3 | E2: กลุ่มลูกค้า ประเภท 4 | F2: LEVEL 2 | G2: LEVEL 3 | H2: LEVEL 4 | I2: ประเภท B2B | J2: กลุ่ม
B3: BIGC - BIGCARD | C3: 6 : Food Retailer | D3: 61 : Street Shop | E3: 6101 : ร้าน/แผงลอย ผัก/ผลไม้/แปรรูปจากผัก ผลไม้ | F3: 6 | G3: 61 | H3: 6101 | I3: Wholesale | J3: DONJAI 1
B4: BIGC - BIGCARD | C4: 6 : Food Retailer | D4: 61 : Street Shop | E4: 6102 : ร้าน/แผงลอย เนื้อสัตว์/แปรรูปจากเนื้อสัตว์ | F4: 6 | G4: 61 | H4: 6102 | I4: Wholesale | J4: DONJAI 1
B5: BIGC - BIGCARD | C5: 6 : Food Retailer | D5: 61 : Street Shop | E5: 6103 : ร้านค้าอาหารแช่แข็ง/แช่เย็น | F5: 6 | G5: 61 | H5: 6103 | I5: Wholesale | J5: DONJAI 1
B6: BIGC - BIGCARD | C6: 6 : Food Retailer | D6: 62 : SME-Grocery shop | E6: 6201 : ร้านชำ/แผงขายชำ ขนาดน้อยกว่า 200ตรม. | F6: 6 | G6: 62 | H6: 6201 | I6: Wholesale | J6: DONJAI 1
B7: BIGC - BIGCARD | C7: 6 : Food Retailer | D7: 62 : SME-Grocery shop | E7: 6202 : ร้านขายยา และ เครื่องสำอาง | F7: 6 | G7: 62 | H7: 6202 | I7: Wholesale | J7: DONJAI 1
B8: BIGC - BIGCARD | C8: 6 : Food Retailer | D8: 62 : SME-Grocery shop | E8: 6203 : ร้านขายอาหาร ยาสัตว์ อุปกรณ์ และของใช้เกี่ยวกับสัตว์เลี้ยง | F8: 6 | G8: 62 | H8: 6203 | I8: Wholesale | J8: DONJAI 1
B9: BIGC - BIGCARD | C9: 6 : Food Retailer | D9: 62 : SME-Grocery shop | E9: 6204 : ร้านมินิมาร์ท มีกระจกหน้าร้าน มี/ไม่มีแอร์ มีเคาน์เตอร์และชั้นเรียง | F9: 6 | G9: 62 | H9: 6204 | I9: Wholesale | J9: DONJAI 1
B10: BIGC - BIGCARD | C10: 6 : Food Retailer | D10: 62 : SME-Grocery shop | E10: 6205 : ซุปเปอร์มาร์เก็ต ขนาดมากกว่า 200ตรม. มีกระจก มีแอร์ มีเคาน์เตอร์ และรถเข็น | F10: 6 | G10: 62 | H10: 6205 | I10: Wholesale | J10: DONJAI 1
B11: BIGC - BIGCARD | C11: 6 : Food Retailer | D11: 62 : SME-Grocery shop | E11: 6206 : ร้านค้าปลีกสินค้าบริโภค / อาหารสด ในรูปแบบรถเร่ | F11: 6 | G11: 62 | H11: 6206 | I11: Wholesale | J11: DONJAI 1
B12: BIGC - BIGCARD | C12: 6 : Food Retailer | D12: 62 : SME-Grocery shop | E12: 6207 : ร้านค้าปลีกสินค้าบริโภคอื่นๆ/ ร้านโอท็อป-ของฝากสินค้าบริโภค | F12: 6 | G12: 62 | H12: 6207 | I12: Wholesale | J12: DONJAI 1
B13: BIGC - BIGCARD | C13: 6 : Food Retailer | D13: 63 : Retailer RDS | E13: 6301 : ร้านค้าโชว์ห่วย RDS | F13: 6 | G13: 63 | H13: 6301 | I13: Wholesale | J13: DONJAI 1
... B89: BIGC - BIGCARD | C89: 11 : Corporate | D89: 111 : Corporate Group | E89: 1116 : กลุ่มธุรกิจอื่น ๆ | F89: 11 | G89: 111 | H89: 1116 | I89: Wholesale | J89: B2B
B90: BIGC - BIGCARD | C90: 18 : HoReCa Food Services | D90: 181 : FS_Hotel | E90: 1811 : FS_อพาร์ทเมนท์ / หอพัก | F90: =LEFT(C90,2) -> 18 | G90: =LEFT(D90,3) -> 181 | H90: =LEFT(E90,4) -> 1811 | I90: Food Service | J90: FOOD SERVICE
B91: BIGC - BIGCARD | C91: 18 : HoReCa Food Services | D91: 181 : FS_Hotel | E91: 1812 : FS_โรงแรม/รีสอร์ต 1 ดาว | F91: =LEFT(C91,2) -> 18 | G91: =LEFT(D91,3) -> 181 | H91: =LEFT(E91,4) -> 1812 | I91: Food Service | J91: FOOD SERVICE
B92: BIGC - BIGCARD | C92: 18 : HoReCa Food Services | D92: 181 : FS_Hotel | E92: 1813 : FS_โรงแรม/รีสอร์ต 2-3 ดาว | F92: =LEFT(C92,2) -> 18 | G92: =LEFT(D92,3) -> 181 | H92: =LEFT(E92,4) -> 1813 | I92: Food Service | J92: FOOD SERVICE
B93: BIGC - BIGCARD | C93: 18 : HoReCa Food Services | D93: 181 : FS_Hotel | E93: 1814 : FS_โรงแรม/รีสอร์ต 4-5 ดาว | F93: =LEFT(C93,2) -> 18 | G93: =LEFT(D93,3) -> 181 | H93: =LEFT(E93,4) -> 1814 | I93: Food Service | J93: FOOD SERVICE
B94: BIGC - BIGCARD | C94: 18 : HoReCa Food Services | D94: 182 : FS_Restaurant | E94: 1821 : FS_ร้านอาหารไทย | F94: =LEFT(C94,2) -> 18 | G94: =LEFT(D94,3) -> 182 | H94: =LEFT(E94,4) -> 1821 | I94: Food Service | J94: FOOD SERVICE
B95: BIGC - BIGCARD | C95: 18 : HoReCa Food Services | D95: 182 : FS_Restaurant | E95: 1822 : FS_ร้านอาหารอีสาน | F95: =LEFT(C95,2) -> 18 | G95: =LEFT(D95,3) -> 182 | H95: =LEFT(E95,4) -> 1822 | I95: Food Service | J95: FOOD SERVICE
B96: BIGC - BIGCARD | C96: 18 : HoReCa Food Services | D96: 182 : FS_Restaurant | E96: 1823 : FS_ร้านอาหารจีน | F96: =LEFT(C96,2) -> 18 | G96: =LEFT(D96,3) -> 182 | H96: =LEFT(E96,4) -> 1823 | I96: Food Service | J96: FOOD SERVICE
B97: BIGC - BIGCARD | C97: 18 : HoReCa Food Services | D97: 182 : FS_Restaurant | E97: 1824 : FS_ร้านอาหารเวียดนาม | F97: =LEFT(C97,2) -> 18 | G97: =LEFT(D97,3) -> 182 | H97: =LEFT(E97,4) -> 1824 | I97: Food Service | J97: FOOD SERVICE
B98: BIGC - BIGCARD | C98: 18 : HoReCa Food Services | D98: 182 : FS_Restaurant | E98: 1825 : FS_ร้านอาหารญี่ปุ่น | F98: =LEFT(C98,2) -> 18 | G98: =LEFT(D98,3) -> 182 | H98: =LEFT(E98,4) -> 1825 | I98: Food Service | J98: FOOD SERVICE
B99: BIGC - BIGCARD | C99: 18 : HoReCa Food Services | D99: 182 : FS_Restaurant | E99: 1826 : FS_ร้านอาหารเกาหลี | F99: =LEFT(C99,2) -> 18 | G99: =LEFT(D99,3) -> 182 | H99: =LEFT(E99,4) -> 1826 | I99: Food Service | J99: FOOD SERVICE
B100: BIGC - BIGCARD | C100: 18 : HoReCa Food Services | D100: 182 : FS_Restaurant | E100: 1827 : FS_ร้านอาหารอินเดีย | F100: =LEFT(C100,2) -> 18 | G100: =LEFT(D100,3) -> 182 | H100: =LEFT(E100,4) -> 1827 | I100: Food Service | J100: FOOD SERVICE
B101: BIGC - BIGCARD | C101: 18 : HoReCa Food Services | D101: 182 : FS_Restaurant | E101: 1828 : FS_ร้านอาหารมุสลิม | F101: =LEFT(C101,2) -> 18 | G101: =LEFT(D101,3) -> 182 | H101: =LEFT(E101,4) -> 1828 | I101: Food Service | J101: FOOD SERVICE
... B118: BIGC - BIGCARD | C118: 18 : HoReCa Food Services | D118: 187 : FS_Entertainment | E118: 1871 : FS_สถานบันเทิง ผับ/บาร์/คาราโอเกะ/อาบอบนวด | F118: =LEFT(C118,2) -> 18 | G118: =LEFT(D118,3) -> 187 | H118: =LEFT(E118,4) -> 1871 | I118: Food Service | J118: FOOD SERVICE

Sheet Index
B2: กลุ่มลูกค้า ประเภท 2 | C2: กลุ่มลูกค้า ประเภท 3 | D2: กลุ่มลูกค้า ประเภท 4
B3: 6 : Food Retailer | C3: 61 : Street Shop | D3: 6101 : ร้าน/แผงลอย ผัก/ผลไม้/แปรรูปจากผัก ผลไม้
B4: 7 : Non Food Retailer | C4: 62 : SME-Grocery shop | D4: 6102 : ร้าน/แผงลอย เนื้อสัตว์/แปรรูปจากเนื้อสัตว์
B5: 8 : HoReCa | C5: 63 : Retailer RDS | D5: 6103 : ร้านค้าอาหารแช่แข็ง/แช่เย็น
B6: 9 : Services | C6: 71 : Business User | D6: 6201 : ร้านชำ/แผงขายชำ ขนาดน้อยกว่า 200ตรม.
B7: 10 : Distributor | C7: 72 : SME-Non food shop | D7: 6202 : ร้านขายยา และ เครื่องสำอาง
B8: 11 : Corporate | C8: 81 : Hotel | D8: 6203 : ร้านขายอาหาร ยาสัตว์ อุปกรณ์ และของใช้เกี่ยวกับสัตว์เลี้ยง
B9: 18 : HoReCa Food Services | C9: 82 : Restaurant | D9: 6204 : ร้านมินิมาร์ท มีกระจกหน้าร้าน มี/ไม่มีแอร์ มีเคาน์เตอร์และชั้นเรียง
C10: 83 : Catering | D10: 6205 : ซุปเปอร์มาร์เก็ต ขนาดมากกว่า 200ตรม. มีกระจก มีแอร์ มีเคาน์เตอร์ และรถเข็น
C11: 84 : Food Chain | D11: 6206 : ร้านค้าปลีกสินค้าบริโภค / อาหารสด ในรูปแบบรถเร่
C12: 85 : Cafe & Coffee | D12: 6207 : ร้านค้าปลีกสินค้าบริโภคอื่นๆ/ ร้านโอท็อป-ของฝากสินค้าบริโภค
C13: 86 : Entertainment | D13: 6301 : ร้านค้าโชว์ห่วย RDS
C14: 91 : Service business | D14: 7101 : ร้านขายมอเตอร์ไซต์/อะไหล่/ซ่อม
C15: 92 : Organization | D15: 7102 : ร้านขายจักรยาน/อะไหล่/ซ่อม
C16: 93 : Company | D16: 7103 : ร้าน โชว์รูมขายรถยนต์/ประดับยนต์
C17: 94 : Manufacturing | D17: 7104 : ร้านขายอุปกรณ์ก่อสร้าง
C18: 101 : Food | D18: 7105 : ร้านขายเสื้อผ้าเย็บปัก
C19: 102 : Non Food | D19: 7106 : ร้านเพชรทอง
C20: 103 : Import&Export | D20: 7201 : ร้านขายเครื่องเขียน อุปกรณ์การเรียน
C21: 111 : Corporate Group | D21: 7202 : ร้านขายอุปกรณ์ และเครื่องใช้สำนักงาน ขายคอมพิวเตอร์
... C28: 187 : FS_Entertainment | D28: 7209 : ร้านขายปุ๋ย/สินค้าเกี่ยวกับการเกษตร/ผลิตภัณฑ์การเกษตร
D29: 8101 : อพาร์ทเมนท์ / หอพัก
D30: 8102 : โรงแรม/รีสอร์ต 1 ดาว
D31: 8103 : โรงแรม/รีสอร์ต 2-3 ดาว
D32: 8104 : โรงแรม/รีสอร์ต 4-5 ดาว
D33: 8201 : ร้านอาหารไทย
D34: 8202 : ร้านอาหารอีสาน
D35: 8203 : ร้านอาหารจีน
D36: 8204 : ร้านอาหารเวียดนาม
D37: 8205 : ร้านอาหารญี่ปุ่น
D38: 8206 : ร้านอาหารเกาหลี
D39: 8207 : ร้านอาหารอินเดีย
D40: 8208 : ร้านอาหารมุสลิม
... D118: 1871 : FS_สถานบันเทิง ผับ/บาร์/คาราโอเกะ/อาบอบนวด

Sheet Request_B2B
A1: Request B2B Food Retail :
A2: Store Request -- > ………11111…โคราช…กิจการ ร้านธงฟ้าประชารัฐ รวยรินทร์ บ้านหนองยาง อ.เฉลิมพระเกียรติ ชื่อรวยรินทร์ จุฑามณี วันที่ต้องการขาย (10 - 16 ตุลาคม 2561)
A3: Store Request | W3: Member | AA3: Buyer Feedback | AC3: Store Confirm order
A4: Store No | B4: Dept | C4: Article | D4: Barcode | E4: Description | F4: Packsize | G4: Avg. Cost price | H4: Cost (In_Vat) | I4: Normal Price | J4: Selling Price B2B FOOD SERVICE PRICE | K4: Normal GP% | L4: Store Request price | M4: GP | N4: TOTAL GP AMOUNT | O4: Condition/ Reference | P4: Qty/Pack | Q4: Total Quantity / Kg (จำนวนที่ต้องการขาย) | R4: Sales Value ฿ | S4: Quantity by customer/month | T4: กำหนดวันขายสินค้า | U4: PO Order เลขที่ใบสั่งซื้อ | V4: Delivery Date กำหนดวันสินค้าส่งเข้าสาขา | W4: Member No. | X4: Member Name | Y4: ชื่อกิจการ | Z4: Contact Tel. | AA4: Price Approve | AB4: Disagreed / ( How / Reason ) | AC4: Quantity (case) | AD4: Amt.
A5: 11111 Korat | B5: 4 DRY FOOD | C5: 101046300 | D5: 8850456102054 | E5: น้ำตาลดีเมอเรร่าวังขนาย 1 กก. | F5: 25 | G5: 19.4 | H5: =G5*1.07 -> 20.758 | I5: 23 | J5: 22.5 | K5: =SUM(J5-H5)/J5 -> 0.077422222 | L5: 22 | M5: =SUM(L5-H5)/L5 -> 0.056454545 | N5: =((L5/1.07)-G5)*Q5 -> 145.09346 | P5: 5 | Q5: =P5*F5 -> 125 | R5: =Q5*L5 -> 2750 | T5: 10 - 15 ตุลาคม 2561 | W5: 1111111101222403 | X5: คุณรวยนรินทร์ จุฑามณี | Y5: ร้านรวยรินทร์ (ประชารัฐ) | Z5: 083-1291463 | AA5: 22
A6: 11111 Korat | B6: 4 DRY FOOD | C6: 102203276 | D6: 8855199143012 | E6: โค้ก 1.5 ลิตร | F6: 12 | G6: 22.2 | H6: =G6*1.07 -> 23.754 | I6: 26 | J6: 24 | K6: =SUM(J6-H6)/J6 -> 0.01025 | L6: 24 | M6: =SUM(L6-H6)/L6 -> 0.01025 | N6: =((L6/1.07)-G6)*Q6 -> 27.588785 | P6: 10 | Q6: =P6*F6 -> 120 | R6: =Q6*L6 -> 2880 | T6: 10 - 15 ตุลาคม 2561 | W6: 1111111101222403 | X6: คุณรวยนรินทร์ จุฑามณี | Y6: ร้านรวยรินทร์ (ประชารัฐ) | Z6: 083-1291463 | AA6: 24
A7: 11111 Korat | B7: 4 DRY FOOD | D7: 8850206011025 | E7: ซีอิ้วขาวสูตร1เด็กสมบูรณ์700ซี(M) | F7: 4 | G7: 35.75 | H7: =G7*1.07 -> 38.2525 | I7: 39.5 | J7: 39 | K7: =SUM(J7-H7)/J7 -> 0.019166667 | L7: 34 | M7: =SUM(L7-H7)/L7 -> -0.12507353 | N7: =((L7/1.07)-G7)*Q7 -> -238.45794 | O7: in store promotion @34 | P7: 15 | Q7: =P7*F7 -> 60 | R7: =Q7*L7 -> 2040 | T7: 10 - 15 ตุลาคม 2561 | W7: 1111111101222403 | X7: คุณรวยนรินทร์ จุฑามณี | Y7: ร้านรวยรินทร์ (ประชารัฐ) | Z7: 083-1291463 | AA7: 39 | AB7: ราคา34.-in storeมีผลถึง10/10/18 เท่านั้น
A8: 11111 Korat | B8: 4 DRY FOOD | C8: 102509217 | D8: 8851932377287 | E8: บรีส เอกเซล คัลเลอร์ 1900 กรัม | F8: 6 | G8: 146.97 | H8: =G8*1.07 -> 157.2579 | I8: 165 | J8: 110 | K8: =SUM(J8-H8)/J8 -> -0.42961727 | L8: 110 | M8: =SUM(L8-H8)/L8 -> -0.42961727 | N8: =((L8/1.07)-G8)*Q8 -> -529.99514 | O8: B2B price มีผล 18-29/10/61 ถ้าสามารถอนุมัติให้ขายจะสั่งพร้อมกันทั้งหมดตามรายการที่ขอราคาค่ะ | P8: 2 | Q8: =P8*F8 -> 12 | R8: =Q8*L8 -> 1320 | T8: 10 - 15 ตุลาคม 2561 | W8: 1111111101222403 | X8: คุณรวยนรินทร์ จุฑามณี | Y8: ร้านรวยรินทร์ (ประชารัฐ) | Z8: 083-1291463 | AA8: 165 | AB8: หรือสั่งและรวมVolume ขายได้มากกว่า 10 ลัง ถึงจะได้ราคา 110.-(WSHL)
A9: 11111 Korat | B9: 4 DRY FOOD | C9: 102509215 | D9: 8851932377485 | E9: บรีส เอกเซล 2000 กรัม. | F9: 6 | G9: 146.97 | H9: =G9*1.07 -> 157.2579 | I9: 165 | J9: 110 | K9: =SUM(J9-H9)/J9 -> -0.42961727 | L9: 110 | M9: =SUM(L9-H9)/L9 -> -0.42961727 | N9: =((L9/1.07)-G9)*Q9 -> -529.99514 | P9: 2 | Q9: =P9*F9 -> 12 | R9: =Q9*L9 -> 1320 | T9: 10 - 15 ตุลาคม 2561 | W9: 1111111101222403 | X9: คุณรวยนรินทร์ จุฑามณี | Y9: ร้านรวยรินทร์ (ประชารัฐ) | Z9: 083-1291463 | AA9: 165
A10: 11111 Korat | B10: 4 DRY FOOD | C10: 102509216 | D10: 8851932377836 | E10: บรีส เอกเซล คอมฟอร์ท 1900 ก. | F10: 6 | G10: 146.97 | H10: =G10*1.07 -> 157.2579 | I10: 165 | J10: 110 | K10: =SUM(J10-H10)/J10 -> -0.42961727 | L10: 110 | M10: =SUM(L10-H10)/L10 -> -0.42961727 | N10: =((L10/1.07)-G10)*Q10 -> -529.99514 | P10: 2 | Q10: =P10*F10 -> 12 | R10: =Q10*L10 -> 1320 | T10: 10 - 15 ตุลาคม 2561 | W10: 1111111101222403 | X10: คุณรวยนรินทร์ จุฑามณี | Y10: ร้านรวยรินทร์ (ประชารัฐ) | Z10: 083-1291463 | AA10: 165
A11: 11111 Korat | B11: 4 DRY FOOD | C11: 102509218 | D11: 8851932380959 | E11: บรีส คอมฟอร์ท ม่วง 1900 กรัม. | F11: 6 | G11: 146.97 | H11: =G11*1.07 -> 157.2579 | I11: 165 | J11: 110 | K11: =SUM(J11-H11)/J11 -> -0.42961727 | L11: 110 | M11: =SUM(L11-H11)/L11 -> -0.42961727 | N11: =((L11/1.07)-G11)*Q11 -> -529.99514 | P11: 2 | Q11: =P11*F11 -> 12 | R11: =Q11*L11 -> 1320 | T11: 10 - 15 ตุลาคม 2561 | W11: 1111111101222403 | X11: คุณรวยนรินทร์ จุฑามณี | Y11: ร้านรวยรินทร์ (ประชารัฐ) | Z11: 083-1291463 | AA11: 165
A12: 11111 Korat | B12: 4 DRY FOOD | C12: 102173850 | D12: 8850127063929 | E12: น้ำดื่มเนสเล่330 มล. แพ็ค 12 | F12: 1 | G12: 38.32 | H12: =G12*1.07 -> 41.0024 | I12: 51 | J12: 45 | K12: =SUM(J12-H12)/J12 -> 0.088835556 | L12: 43 | M12: =SUM(L12-H12)/L12 -> 0.046455814 | N12: =((L12/1.07)-G12)*Q12 -> 560.07477 | O12: ลูกค้าขอให้เสนอเพื่อเลือกรายการใดรายการหนึ่ง | P12: 300 | Q12: =P12*F12 -> 300 | R12: =Q12*L12 -> 12900 | T12: 10 - 15 ตุลาคม 2561 | W12: 1111111101222403 | X12: คุณรวยนรินทร์ จุฑามณี | Y12: ร้านรวยรินทร์ (ประชารัฐ) | Z12: 083-1291463 | AA12: 43
A13: 11111 Korat | B13: 4 DRY FOOD | C13: 102245707 | D13: 8851952150808 | E13: น้ำดื่มคริสตัล 330 ซีซี. แพ็ค 12 | F13: 1 | G13: 44.88 | H13: =G13*1.07 -> 48.0216 | I13: 51 | J13: 51 | K13: =SUM(J13-H13)/J13 -> 0.0584 | L13: 45 | M13: =SUM(L13-H13)/L13 -> -0.067146667 | N13: =((L13/1.07)-G13)*Q13 -> -847.17757 | P13: 300 | Q13: =P13*F13 -> 300 | R13: =Q13*L13 -> 13500 | T13: 10 - 15 ตุลาคม 2561 | W13: 1111111101222403 | X13: คุณรวยนรินทร์ จุฑามณี | Y13: ร้านรวยรินทร์ (ประชารัฐ) | Z13: 083-1291463 | AA13: 49
A14: 11111 Korat | B14: 4 DRY FOOD | C14: 100614227 | D14: 8850545777552 | E14: น้ำปลาแท้ตราทิพรสขวดเพ็ท700CC(M) | F14: 12 | G14: 24.54 | H14: =G14*1.07 -> 26.2578 | I14: 27.5 | J14: 27 | K14: =SUM(J14-H14)/J14 -> 0.027488889 | L14: 24 | M14: =SUM(L14-H14)/L14 -> -0.094075 | N14: =((L14/1.07)-G14)*Q14 -> -126.60561 | O14: ขอราคาเท่ากับราคาโปรโมชั่น 5-7 ต.ค. | P14: 5 | Q14: =P14*F14 -> 60 | R14: =Q14*L14 -> 1440 | T14: 10 - 15 ตุลาคม 2561 | W14: 1111111101222403 | X14: คุณรวยนรินทร์ จุฑามณี | Y14: ร้านรวยรินทร์ (ประชารัฐ) | Z14: 083-1291463 | AA14: 27 | AB14: ราคา 24.- Pro. ไทยรัฐ มีผลถึง7/10/18
A15: 11111 Korat | B15: 4 DRY FOOD | C15: 100507622 | D15: 8850423000093 | E15: น้ำหวานเฮลซ์บลูบอย710ซีซีสละ(M) | F15: 12 | G15: 37.98 | H15: =G15*1.07 -> 40.6386 | I15: 43 | J15: 42 | K15: =SUM(J15-H15)/J15 -> 0.032414286 | L15: 40.5 | M15: =SUM(L15-H15)/L15 -> -0.0034222222 | N15: =((L15/1.07)-G15)*Q15 -> -15.543925 | O15: B2B ราคา 486 / ลัง ลูกค้าซื้อ | P15: 10 | Q15: =P15*F15 -> 120 | R15: =Q15*L15 -> 4860 | T15: 10 - 15 ตุลาคม 2561 | W15: 1111111101222403 | X15: คุณรวยนรินทร์ จุฑามณี | Y15: ร้านรวยรินทร์ (ประชารัฐ) | Z15: 083-1291463 | AA15: 42 | AB15: หรือสั่งและรวมVolume ขาย มากกว่า5ลัง>>ราคา498/ลัง มากกว่า10ลัง>>ราคา486/ลัง
A16: 11111 Korat | B16: 4 DRY FOOD | C16: 100996692 | D16: 8851932187428 | E16: ซันไลต์เลมอนเทอร์โบ 550มล. | F16: 24 | G16: 24.86 | H16: =G16*1.07 -> 26.6002 | I16: 28 | J16: 24 | K16: =SUM(J16-H16)/J16 -> -0.10834167 | L16: 24 | M16: =SUM(L16-H16)/L16 -> -0.10834167 | N16: =((L16/1.07)-G16)*Q16 -> -58.322243 | P16: 1 | Q16: =P16*F16 -> 24 | R16: =Q16*L16 -> 576 | T16: 10 - 15 ตุลาคม 2561 | W16: 1111111101222403 | X16: คุณรวยนรินทร์ จุฑามณี | Y16: ร้านรวยรินทร์ (ประชารัฐ) | Z16: 083-1291463 | AA16: 27
A17: 11111 Korat | B17: 4 DRY FOOD | C17: 102256576 | D17: 8851494007523 | E17: น้ำมันปาร์มเกสร | F17: 12 | G17: 29.5 | H17: =G17*1.07 -> 31.565 | I17: 42 | J17: 42 | K17: =SUM(J17-H17)/J17 -> 0.24845238 | L17: 30 | M17: =SUM(L17-H17)/L17 -> -0.052166667 | N17: =((L17/1.07)-G17)*Q17 -> -175.51402 | O17: NEW REQUEST | P17: 10 | Q17: =P17*F17 -> 120 | R17: =Q17*L17 -> 3600 | T17: 10 - 15 ตุลาคม 2561 | W17: 1111111101222403 | X17: คุณรวยนรินทร์ จุฑามณี | Y17: ร้านรวยรินทร์ (ประชารัฐ) | Z17: 083-1291463 | AA17: 30
A18: 11111 Korat | B18: 4 DRY FOOD | C18: 102098794 | D18: 8850718701438 | E18: เลย์แผ่นหยักรสเกลือ 52g | F18: 8 | G18: 91.36 | H18: =G18*1.07 -> 97.7552 | I18: 103 | J18: 103 | K18: =SUM(J18-H18)/J18 -> 0.050920388 | L18: 99 | M18: =SUM(L18-H18)/L18 -> 0.012573737 | N18: =((L18/1.07)-G18)*Q18 -> 74.455327 | O18: NEW REQUEST | P18: 8 | Q18: =P18*F18 -> 64 | R18: =Q18*L18 -> 6336 | T18: 10 - 15 ตุลาคม 2561 | W18: 1111111101222403 | X18: คุณรวยนรินทร์ จุฑามณี | Y18: ร้านรวยรินทร์ (ประชารัฐ) | Z18: 083-1291463 | AA18: 99
A19: 11111 Korat | B19: 4 DRY FOOD | C19: 102098795 | D19: 8850718701445 | E19: เลย์หยักรสบาบีคิว52ก | F19: 8 | G19: 91.36 | H19: =G19*1.07 -> 97.7552 | I19: 103 | J19: 103 | K19: =SUM(J19-H19)/J19 -> 0.050920388 | L19: 99 | M19: =SUM(L19-H19)/L19 -> 0.012573737 | N19: =((L19/1.07)-G19)*Q19 -> 74.455327 | O19: NEW REQUEST | P19: 8 | Q19: =P19*F19 -> 64 | R19: =Q19*L19 -> 6336 | T19: 10 - 15 ตุลาคม 2561 | W19: 1111111101222403 | X19: คุณรวยนรินทร์ จุฑามณี | Y19: ร้านรวยรินทร์ (ประชารัฐ) | Z19: 083-1291463 | AA19: 99
A20: 11111 Korat | B20: 4 DRY FOOD | C20: 102098798 | D20: 8850718701476 | E20: เลย์แผ่นเรียบรสเกลือ52กรัม | F20: 8 | G20: 91.36 | H20: =G20*1.07 -> 97.7552 | I20: 103 | J20: 103 | K20: =SUM(J20-H20)/J20 -> 0.050920388 | L20: 99 | M20: =SUM(L20-H20)/L20 -> 0.012573737 | N20: =((L20/1.07)-G20)*Q20 -> 74.455327 | O20: NEW REQUEST | P20: 8 | Q20: =P20*F20 -> 64 | R20: =Q20*L20 -> 6336 | T20: 10 - 15 ตุลาคม 2561 | W20: 1111111101222403 | X20: คุณรวยนรินทร์ จุฑามณี | Y20: ร้านรวยรินทร์ (ประชารัฐ) | Z20: 083-1291463 | AA20: 99
A21: 11111 Korat | B21: 4 DRY FOOD | C21: 102098799 | D21: 8850718701889 | E21: เลยแผ่นเลยเรียบรสโนริ52ก | F21: 8 | G21: 91.36 | H21: =G21*1.07 -> 97.7552 | I21: 103 | J21: 103 | K21: =SUM(J21-H21)/J21 -> 0.050920388 | L21: 99 | M21: =SUM(L21-H21)/L21 -> 0.012573737 | N21: =((L21/1.07)-G21)*Q21 -> 74.455327 | O21: NEW REQUEST | P21: 8 | Q21: =P21*F21 -> 64 | R21: =Q21*L21 -> 6336 | T21: 10 - 15 ตุลาคม 2561 | W21: 1111111101222403 | X21: คุณรวยนรินทร์ จุฑามณี | Y21: ร้านรวยรินทร์ (ประชารัฐ) | Z21: 083-1291463 | AA21: 99
A22: 11111 Korat | B22: 04 DRY FOOD | C22: 102379568 | D22: 8851932353861 | E22: ซันซิลแชมพูสีเขียว 450 มล. | F22: 12 | G22: 106.36 | H22: =G22*1.07 -> 113.8052 | I22: 129 | J22: 79 | K22: =SUM(J22-H22)/J22 -> -0.44057215 | L22: 69 | M22: =SUM(L22-H22)/L22 -> -0.64935072 | N22: =((L22/1.07)-G22)*Q22 -> -502.48822 | O22: ลูกค้าขอคละสี และคละแชมพู กับ ครีมบำรุงผม รวม 10 ลัง ขอราคาพิเศษเท่ากับ Big volume | P22: 1 | Q22: =P22*F22 -> 12 | R22: =Q22*L22 -> 828 | T22: 10 - 15 ตุลาคม 2561 | W22: 1111111101222403 | X22: คุณรวยนรินทร์ จุฑามณี | Y22: ร้านรวยรินทร์ (ประชารัฐ) | Z22: 083-1291463 | AA22: 76 | AB22: หรือสั่งและรวมVolume ขายได้มากกว่า 10 ลัง ถึงจะได้ราคา 69.-(WSHL)
A23: 11111 Korat | B23: 04 DRY FOOD | C23: 102379565 | D23: 8851932353830 | E23: ซันซิลแชมพูสีชมพู 450 มล. | F23: 12 | G23: 106.36 | H23: =G23*1.07 -> 113.8052 | I23: 129 | J23: 79 | K23: =SUM(J23-H23)/J23 -> -0.44057215 | L23: 69 | M23: =SUM(L23-H23)/L23 -> -0.64935072 | N23: =((L23/1.07)-G23)*Q23 -> -502.48822 | P23: 1 | Q23: =P23*F23 -> 12 | R23: =Q23*L23 -> 828 | T23: 10 - 15 ตุลาคม 2561 | W23: 1111111101222403 | X23: คุณรวยนรินทร์ จุฑามณี | Y23: ร้านรวยรินทร์ (ประชารัฐ) | Z23: 083-1291463 | AA23: 76
A24: 11111 Korat | B24: 04 DRY FOOD | C24: 102379566 | D24: 8851932353847 | E24: ซันซิลแชมพูสีม่วง 450 มล. | F24: 12 | G24: 106.36 | H24: =G24*1.07 -> 113.8052 | I24: 129 | J24: 79 | K24: =SUM(J24-H24)/J24 -> -0.44057215 | L24: 69 | M24: =SUM(L24-H24)/L24 -> -0.64935072 | N24: =((L24/1.07)-G24)*Q24 -> -502.48822 | P24: 1 | Q24: =P24*F24 -> 12 | R24: =Q24*L24 -> 828 | T24: 10 - 15 ตุลาคม 2561 | W24: 1111111101222403 | X24: คุณรวยนรินทร์ จุฑามณี | Y24: ร้านรวยรินทร์ (ประชารัฐ) | Z24: 083-1291463 | AA24: 76
A25: 11111 Korat | B25: 04 DRY FOOD | C25: 102379567 | D25: 8851932353854 | E25: ซันซิลแชมพูสีส้ม 450 มล. | F25: 12 | G25: 106.36 | H25: =G25*1.07 -> 113.8052 | I25: 129 | J25: 79 | K25: =SUM(J25-H25)/J25 -> -0.44057215 | L25: 69 | M25: =SUM(L25-H25)/L25 -> -0.64935072 | N25: =((L25/1.07)-G25)*Q25 -> -502.48822 | P25: 1 | Q25: =P25*F25 -> 12 | R25: =Q25*L25 -> 828 | T25: 10 - 15 ตุลาคม 2561 | W25: 1111111101222403 | X25: คุณรวยนรินทร์ จุฑามณี | Y25: ร้านรวยรินทร์ (ประชารัฐ) | Z25: 083-1291463 | AA25: 76
A26: 11111 Korat | B26: 04 DRY FOOD | C26: 102379564 | D26: 8851932353823 | E26: ซันซิลแชมพูสีเขียว 450 มล. | F26: 12 | G26: 106.36 | H26: =G26*1.07 -> 113.8052 | I26: 129 | J26: 79 | K26: =SUM(J26-H26)/J26 -> -0.44057215 | L26: 69 | M26: =SUM(L26-H26)/L26 -> -0.64935072 | N26: =((L26/1.07)-G26)*Q26 -> -502.48822 | P26: 1 | Q26: =P26*F26 -> 12 | R26: =Q26*L26 -> 828 | T26: 10 - 15 ตุลาคม 2561 | W26: 1111111101222403 | X26: คุณรวยนรินทร์ จุฑามณี | Y26: ร้านรวยรินทร์ (ประชารัฐ) | Z26: 083-1291463 | AA26: 76
A27: 11111 Korat | B27: 04 DRY FOOD | C27: 102379595 | D27: 8851932354295 | E27: ซันซิลครีมบำรุงผมสีเขียว 450 มล. | F27: 12 | G27: 106.36 | H27: =G27*1.07 -> 113.8052 | I27: 129 | J27: 79 | K27: =SUM(J27-H27)/J27 -> -0.44057215 | L27: 69 | M27: =SUM(L27-H27)/L27 -> -0.64935072 | N27: =((L27/1.07)-G27)*Q27 -> -502.48822 | O27: Big Volume ซื้อ 120 ขึ้นไป เหลือ 69 บ. | P27: 1 | Q27: =P27*F27 -> 12 | R27: =Q27*L27 -> 828 | T27: 10 - 15 ตุลาคม 2561 | W27: 1111111101222403 | X27: คุณรวยนรินทร์ จุฑามณี | Y27: ร้านรวยรินทร์ (ประชารัฐ) | Z27: 083-1291463 | AA27: 76 | AB27: หรือสั่งและรวมVolume ขายได้มากกว่า 10 ลัง ถึงจะได้ราคา 69.-(WSHL)
A28: 11111 Korat | B28: 04 DRY FOOD | C28: 102379592 | D28: 8851932354264 | E28: ซันซิลครีมบำรุงผมสีชมพู 450 มล. | F28: 12 | G28: 106.36 | H28: =G28*1.07 -> 113.8052 | I28: 129 | J28: 79 | K28: =SUM(J28-H28)/J28 -> -0.44057215 | L28: 69 | M28: =SUM(L28-H28)/L28 -> -0.64935072 | N28: =((L28/1.07)-G28)*Q28 -> -502.48822 | P28: 1 | Q28: =P28*F28 -> 12 | R28: =Q28*L28 -> 828 | T28: 10 - 15 ตุลาคม 2561 | W28: 1111111101222403 | X28: คุณรวยนรินทร์ จุฑามณี | Y28: ร้านรวยรินทร์ (ประชารัฐ) | Z28: 083-1291463 | AA28: 76
A29: 11111 Korat | B29: 4 DRY FOOD | C29: 102379593 | D29: 8851932354271 | E29: ซันซิลครีมบำรุงผมสีม่วง 450 มล. | F29: 12 | G29: 106.36 | H29: =G29*1.07 -> 113.8052 | I29: 129 | J29: 79 | K29: =SUM(J29-H29)/J29 -> -0.44057215 | L29: 69 | M29: =SUM(L29-H29)/L29 -> -0.64935072 | N29: =((L29/1.07)-G29)*Q29 -> -502.48822 | P29: 1 | Q29: =P29*F29 -> 12 | R29: =Q29*L29 -> 828 | T29: 10 - 15 ตุลาคม 2561 | W29: 1111111101222403 | X29: คุณรวยนรินทร์ จุฑามณี | Y29: ร้านรวยรินทร์ (ประชารัฐ) | Z29: 083-1291463 | AA29: 76
A30: 11111 Korat | B30: 4 DRY FOOD | C30: 102379594 | D30: 8851932354288 | E30: ซันซิลครีมบำรุงผมสีส้ม 450 มล. | F30: 12 | G30: 106.36 | H30: =G30*1.07 -> 113.8052 | I30: 129 | J30: 79 | K30: =SUM(J30-H30)/J30 -> -0.44057215 | L30: 69 | M30: =SUM(L30-H30)/L30 -> -0.64935072 | N30: =((L30/1.07)-G30)*Q30 -> -502.48822 | P30: 1 | Q30: =P30*F30 -> 12 | R30: =Q30*L30 -> 828 | T30: 10 - 15 ตุลาคม 2561 | W30: 1111111101222403 | X30: คุณรวยนรินทร์ จุฑามณี | Y30: ร้านรวยรินทร์ (ประชารัฐ) | Z30: 083-1291463 | AA30: 76
A31: 11111 Korat | B31: 4 DRY FOOD | C31: 102379591 | D31: 8851932354257 | E31: ซันซิลครีมบำรุงผมสีเขียว 450 มล. | F31: 12 | G31: 106.36 | H31: =G31*1.07 -> 113.8052 | I31: 129 | J31: 79 | K31: =SUM(J31-H31)/J31 -> -0.44057215 | L31: 69 | M31: =SUM(L31-H31)/L31 -> -0.64935072 | N31: =((L31/1.07)-G31)*Q31 -> -502.48822 | P31: 1 | Q31: =P31*F31 -> 12 | R31: =Q31*L31 -> 828 | T31: 10 - 15 ตุลาคม 2561 | W31: 1111111101222403 | X31: คุณรวยนรินทร์ จุฑามณี | Y31: ร้านรวยรินทร์ (ประชารัฐ) | Z31: 083-1291463 | AA31: 76
A32: Total | M32: =N32/R32 -> -0.090783772 | N32: =SUM(N5:N31) -> -7575.9058 | P32: 0 | Q32: =SUM(Q5:Q31) -> 1653 | R32: =SUM(R5:S31) -> 83450 | AD32: =+AC32*AA32*F32/1.07 -> 0

Sheet Questionaire
A2: แบบสอบถามสำหรับออกพบลูกค้า
A5: ข้อ 1. ท่านเคยใช้บริการในห้างบิ๊กซีหรือไม่ | T5: ข้อ 4. ท่านซื้อของที่บิ๊กซีบ่อยแค่ไหน
A6: £เคย | T6: £2-3 วัน / ครั้ง
A7: £ไม่เคย | T7: £1 อาทิตย์ / ครั้ง
A8: ข้อ 2.เหตุผลหลักที่ท่านเลือกใช้บริการที่บิ๊กซี (ตอบได้มากกว่า 1 ข้อ) | T8: £15 วัน / ครั้ง
A9: £สินค้ามีหลากหลาย ไม่ต้องไปหลายที่ | T9: £1 เดือน / ครั้ง
A10: £ใกล้ สะดวกในการเดินทาง | T10: £อื่นๆ_______________________
A11: £สินค้าคุณภาพดี ราคาถูก | T11: หมายเหตุ
A12: £ไม่ต้องสต็อกสินค้ามาก | T12: ในข้ออื่นๆ ส่วนใหญ่แล้วลูกค้าไม่ได้มานานกว่า 1 เดือน
A13: £พอใจในการบริการ
A14: £อื่นๆ_______________________
A15: ข้อ 3. ประเภทสินค้าที่ซื้อในบิ๊กซี (ตอบได้มากกว่า 1 ข้อ) | T15: ข้อ 5.นอกจากบิ๊กซีแล้ว ท่านซื้อของจากที่ใดบ้าง
A16: £เครื่องดื่ม (เหล้า เบียร์ น้ำอัดลม) | T16: £เทสโก้ โลตัส
A17: £อาหารสด | T17: £Big C
A18: £ขนมขบเคี้ยว | T18: £ท็อฟฟี่
A19: £เครื่องใช้ไฟฟ้า | T19: £น่ำเส็ง
A20: £เครื่องใช้สำนักงาน | T20: £วงศ์มังกร
A21: £เครื่องปรุง/ของใช้ในครัวเรือน | T21: £505
A22: £อื่นๆ_______________________ | T22: £หน่วยรถของบริษัท (สหพัฒน์,ยูนิลีเวอร์ หรืออื่นๆ)
T23: £ตลาดสด_______________________
T24: £ร้านส่ง_______________________
T25: £อื่นๆ __________________________
A28: ข้อ 6.ปัญหาที่พบบ่อยๆในขณะที่มาใช้บริการที่ห้างบิ๊กซี
A29: พนักงาน / การบริการ | S29: สินค้า
A30: £1.แคชเชียร์คิดเงินช้า / มีน้อย | S30: £1.ป้ายราคาสินค้าไม่ตรง
A31: £2.พนักงานแผนก______________พูดจาไม่สุภาพ | S31: £2.สินค้าที่ลงใน Brochure หมดเร็ว
A32: £3.พนักงานไม่สนใจลูกค้า/ให้คำตอบไม่ชัดเจน | S32: £3.ราคาสินค้าบางตัวแพง
A33: £4.ไม่มีพนักงานช่วยยก/เข็นสินค้าขึ้นรถ | S33: £4.สินค้าขาดสต็อกบ่อย
A34: £5.แคชเชียร์ไม่แจ้งเรื่องการแถมสินค้า/ส่วนลด | S34: £5.ราคาสินค้าสูงกว่าห้างอื่นๆ
A35: £6.แคชเชียร์คิดเงินผิด | S35: £6.สินค้าคุณภาพไม่ดี
A36: £7.แคชเชียร์จับสินค้าแรง ทำให้เกิดความเสียหาย | S36: £7.หาสินค้าไม่ค่อยเจอ
A37: £8.ติดต่อซื้อสินค้ามาแล้วไม่ได้ตามที่สั่ง/ได้ช้า/ติดต่อไม่ได้ | S37: £8.ของแถมน้อย
S38: £9.อาหารสดมีกลิ่น,ไม่สด
A39: ทั่วไป | S39: £10.จำกัดจำนวนสินค้า
A40: £1.อากาศร้อน | S40: £11.เปลี่ยนสินค้ายาก
A41: £2.Brochure ไม่มีจัดส่ง / มีบางพื้นที่ | S41: £12.ชั้นวางไม่มีสินค้าโชว์
A42: £3.ถุงบางเกินไป | S42: £13.สินค้าแลกซื้อไม่เป็นที่นิยม
A43: £4.รถเข็นฝืด/เก่า | S43: £14.สินค้าไม่หลากหลาย บางอย่างไม่มี
A44: £5.เดินทางไม่สะดวก(ไม่มีรถ) | S44: กรุณาระบุ ____________________
A45: £6.ตาชั่งที่แผนกอาหารสดมีน้อย
...

Sheet Visit Form
C2: แบบฟอร์ม ออกเยี่ยมลูกค้า
C3: Visit/Call Form
A4: สาขา | C4: 11110 Khon Kaen
F5: ผู้ตรวจสอบ
A6: ลำดับ | B6: รหัสสมาชิก | C6: ชื่อ นามสกุล | D6: ชื่อกิจการ | E6: เบอร์โทร | F6: เจ้าหน้าที่ B2B | G6: M1 / Duty Mgr.
A7: 43130 | C7: กรรณีการ์ อินทองชู | D7: ร้านบาวดำอาหาร ปักใต้
A8: 43130 | C8: พิลาสลักษณ์ ภูภักดี | D8: ร้านมารวยสุกี้ราดหน้า
A9: 43130 | C9: ธีระพงษ์ ศรีบ้านบาก | D9: ร้านพี่นิดหน่อย อาหารตามสั่ง
A10: 43130 | C10: กนกการลน์ หวันภักดี | D10: ไอแม็คชอป
A11: 43130 | C11: ศิริพรรณ ทายัง | D11: ร้านข้าวมันไก่ ก๋วยเตี๋ยวไก่มข.
A12: 43133 | C12: ไพศาล โคทนา | D12: ร้านสุเมธ
A13: 43133 | C13: สรไกร จันทร์มี | D13: ร้านน้องเมย์หมูทอด
A14: 43133 | C14: ภาสกร บุญทองสุข | D14: ร่านภาสกรยำแซบ
A15: 43133 | C15: ขนิษฐา ชาก์ฐิน | D15: จัดเบรค อบรมทุกวันเสาร์
A16: 43133 | C16: ประภาพรรณ ิพิมพ์ลี | D16: ร้านปากซอยข้าวห่อ
A17: 43133 | C17: ทองสมุทร คำหลอย | D17: ร้านอาหารเติมทรัพย์
A18: 43133 | C18: พิกุล แก้วจอหอ | D18: ร้านผัดไทยหอยทอด - ร้านก๋วยเตี๋ยวน้ำตก
... A25: 43135 | C25: นาตยา มณีทร | D25: ร้านขวัญใจ ข้าวแกง
